<?xml version="1.0"?>
<robot name="warehouse_bot">

  <link name="base_link"></link>

  <link name="chassis">
    <visual>
      <geometry> <box size="0.6 0.4 0.1"/> </geometry>
      <material name="dark_grey"><color rgba="0.2 0.2 0.2 1"/></material>
    </visual>
    <collision>
      <geometry> <box size="0.6 0.4 0.1"/> </geometry>
    </collision>
    <inertial>
      <mass value="2.0"/>
      <inertia ixx="0.01" ixy="0" ixz="0" iyy="0.01" iyz="0" izz="0.01"/>
    </inertial>
  </link>

  <joint name="chassis_joint" type="fixed">
    <parent link="base_link"/>
    <child link="chassis"/>
    <origin xyz="0 0 0.15"/> 
  </joint>

  <link name="top_deck">
    <visual>
      <geometry> <box size="0.5 0.35 0.02"/> </geometry>
      <material name="industrial_blue"><color rgba="0.1 0.4 0.8 1"/></material>
    </visual>
  </link>

  <joint name="top_deck_joint" type="fixed">
    <parent link="chassis"/>
    <child link="top_deck"/>
    <origin xyz="-0.05 0 0.1"/>
  </joint>

  <link name="cargo_box">
    <visual>
      <geometry> <box size="0.2 0.2 0.15"/> </geometry>
      <material name="orange"><color rgba="1.0 0.5 0 1"/></material>
    </visual>
  </link>

  <joint name="cargo_joint" type="fixed">
    <parent link="top_deck"/>
    <child link="cargo_box"/>
    <origin xyz="-0.1 0 0.08"/>
  </joint>

  <link name="left_wheel">
    <visual>
      <geometry> <cylinder radius="0.1" length="0.05"/> </geometry>
      <material name="black"><color rgba="0 0 0 1"/></material>
    </visual>
    <collision>
      <geometry> <cylinder radius="0.1" length="0.05"/> </geometry>
    </collision>
    <inertial>
      <mass value="0.3"/>
      <inertia ixx="0.001" ixy="0" ixz="0" iyy="0.001" iyz="0" izz="0.001"/>
    </inertial>
  </link>

  <joint name="left_wheel_joint" type="continuous">
    <parent link="base_link"/>
    <child link="left_wheel"/>
    <origin xyz="0 0.25 0.1" rpy="-1.5708 0 0"/>
    <axis xyz="0 0 1"/>
  </joint>

  <link name="right_wheel">
    <visual>
      <geometry> <cylinder radius="0.1" length="0.05"/> </geometry>
      <material name="black"><color rgba="0 0 0 1"/></material>
    </visual>
    <collision>
      <geometry> <cylinder radius="0.1" length="0.05"/> </geometry>
    </collision>
    <inertial>
      <mass value="0.3"/>
      <inertia ixx="0.001" ixy="0" ixz="0" iyy="0.001" iyz="0" izz="0.001"/>
    </inertial>
  </link>

  <joint name="right_wheel_joint" type="continuous">
    <parent link="base_link"/>
    <child link="right_wheel"/>
    <origin xyz="0 -0.25 0.1" rpy="-1.5708 0 0"/>
    <axis xyz="0 0 1"/>
  </joint>

  <link name="caster_wheel">
    <visual>
      <geometry> <sphere radius="0.05"/> </geometry>
      <material name="silver"><color rgba="0.7 0.7 0.7 1"/></material>
    </visual>
    <collision>
      <geometry> <sphere radius="0.05"/> </geometry>
    </collision>
    <inertial>
      <mass value="0.1"/>
      <inertia ixx="0.0001" ixy="0" ixz="0" iyy="0.0001" iyz="0" izz="0.0001"/>
    </inertial>
  </link>

  <joint name="caster_joint" type="fixed">
    <parent link="base_link"/>
    <child link="caster_wheel"/>
    <origin xyz="0.25 0 0.05"/>
  </joint>

  <link name="sensor_tower">
    <visual>
      <geometry> <cylinder radius="0.02" length="0.15"/> </geometry>
      <material name="dark_grey"/>
    </visual>
  </link>

  <joint name="tower_joint" type="fixed">
    <parent link="top_deck"/>
    <child link="sensor_tower"/>
    <origin xyz="0.15 0 0.075"/>
  </joint>

  <link name="laser_frame">
    <visual>
      <geometry> <cylinder radius="0.04" length="0.04"/> </geometry>
      <material name="red"><color rgba="1 0 0 1"/></material>
    </visual>
  </link>

  <joint name="laser_joint" type="fixed">
    <parent link="sensor_tower"/>
    <child link="laser_frame"/>
    <origin xyz="0 0 0.08" rpy="0 0 0"/> 
  </joint>

  <gazebo reference="chassis">
    <material>Gazebo/Grey</material>
  </gazebo>
  <gazebo reference="top_deck">
    <material>Gazebo/Blue</material>
  </gazebo>
  <gazebo reference="cargo_box">
    <material>Gazebo/Orange</material>
  </gazebo>

  <gazebo>
    <plugin filename="gz-sim-diff-drive-system" name="gz::sim::systems::DiffDrive">
      <left_joint>left_wheel_joint</left_joint>
      <right_joint>right_wheel_joint</right_joint>
      <wheel_separation>0.5</wheel_separation>
      <wheel_diameter>0.2</wheel_diameter>
      <topic>cmd_vel</topic>
      <odom_topic>odom</odom_topic>
      <tf_topic>/model/my_bot/tf</tf_topic>
      <frame_id>odom</frame_id>
      <child_frame_id>base_link</child_frame_id>
    </plugin>
  </gazebo>

  <gazebo reference="laser_frame">
    <sensor name="laser" type="lidar">
      <pose>0 0 0 0 0 0</pose>
      <visualize>true</visualize>
      <update_rate>10</update_rate>
      <lidar>
        <scan>
          <horizontal>
            <samples>360</samples>
            <min_angle>-3.14</min_angle>
            <max_angle>3.14</max_angle>
          </horizontal>
        </scan>
        <range> <min>0.3</min> <max>12.0</max> </range>
      </lidar>
      <topic>scan</topic>
      <gz_frame_id>laser_frame</gz_frame_id>
    </sensor>
  </gazebo>

</robot>